<?xml version="1.0" encoding="utf-8"?>
<!-- This URDF was automatically created by SolidWorks to URDF Exporter! Originally created by Stephen Brawner (brawner@gmail.com) 
     Commit Version: 1.5.1-0-g916b5db  Build Version: 1.5.7152.31018
     For more information, please see http://wiki.ros.org/sw_urdf_exporter -->
<robot
  name="BYCICLE">
  <link
    name="base_link">
    <inertial>
      <origin
        xyz="1.77635683940025E-15 0 0.03"
        rpy="0 0 0" />
      <mass
        value="6.96438055098074" />
      <inertia
        ixx="0.0080524986263849"
        ixy="-1.9810889379099E-34"
        ixz="-4.41621802874711E-18"
        iyy="0.794777615298062"
        iyz="5.4210108624275E-19"
        izz="0.798651485593858" />
    </inertial>
    <visual>
      <origin
        xyz="0 0 0"
        rpy="0 0 0" />
      <geometry>
        <mesh
          filename="base_link.STL" />
      </geometry>
      <material
        name="red">
        <color
          rgba="1 0 0 1" />
      </material>
    </visual>
    <collision>
      <origin
        xyz="0 0 0"
        rpy="0 0 0" />
      <geometry>
        <mesh
          filename="base_link.STL" />
      </geometry>
    </collision>
  </link>
  <link
    name="FF_Link">
    <inertial>
      <origin
        xyz="-1.35457055883137E-06 -1.15685060864124E-06 -0.322345834514443"
        rpy="0 0 0" />
      <mass
        value="1" />
      <inertia
        ixx="0.09117078802614"
        ixy="-0.000740576263226076"
        ixz="-1.25821123938152E-07"
        iyy="0.0726502812610049"
        iyz="5.82479845404965E-07"
        izz="0.0193972074891309" />
    </inertial>
    <visual>
      <origin
        xyz="0 0 0"
        rpy="0 0 0" />
      <geometry>
        <mesh
          filename="FF_Link.STL" />
      </geometry>
      <material
        name="green">
        <color
          rgba="0 1 0 1" />
      </material>
    </visual>
    <collision>
      <origin
        xyz="0 0 0"
        rpy="0 0 0" />
      <geometry>
        <mesh
          filename="FF_Link.STL" />
      </geometry>
    </collision>
  </link>
  <joint
    name="front_fork"
    type="continuous">
    <origin
      xyz="0.550000000000001 0 0.06"
      rpy="0 0 0" />
    <parent
      link="base_link" />
    <child
      link="FF_Link" />
    <axis
      xyz="0 0 1" />
  </joint>
  <link
    name="FW_Link">
    <inertial>
      <origin
        xyz="-6.00533383021684E-08 -1.50426817135951E-06 -1.67510449955444E-12"
        rpy="0 0 0" />
      <mass
        value="1" />
      <inertia
        ixx="0.141700222564193"
        ixy="0.00555273242193519"
        ixz="6.01773083230338E-05"
        iyy="0.280566973986589"
        iyz="-2.40241757411615E-06"
        izz="0.141308896962391" />
    </inertial>
    <visual>
      <origin
        xyz="0 0 0"
        rpy="0 0 0" />
      <geometry>
        <mesh
          filename="FW_Link.STL" />
      </geometry>
      <material
        name="red">
        <color
          rgba="1 0 0 1" />
      </material>
    </visual>
    <collision>
      <origin
        xyz="0 0 0"
        rpy="0 0 0" />
      <geometry>
        <mesh
          filename="FW_Link.STL" />
      </geometry>
    </collision>
  </link>
  <joint
    name="front_wheel"
    type="continuous">
    <origin
      xyz="0 0 -0.55"
      rpy="0 0 0" />
    <parent
      link="FF_Link" />
    <child
      link="FW_Link" />
    <axis
      xyz="-0.0398905414403981 -0.999204055588042 0" />
  </joint>
  <link
    name="RF_Link">
    <inertial>
      <origin
        xyz="-1.30734499848018E-06 -1.20996437535936E-06 -0.322345834514435"
        rpy="0 0 0" />
      <mass
        value="2.60962214090292" />
      <inertia
        ixx="0.09120035412032"
        ixy="-1.4367005967913E-08"
        ixz="-1.48956413746679E-07"
        iyy="0.0726207151668"
        iyz="5.76997150915664E-07"
        izz="0.0193972074891295" />
    </inertial>
    <visual>
      <origin
        xyz="0 0 0"
        rpy="0 0 0" />
      <geometry>
        <mesh
          filename="RF_Link.STL" />
      </geometry>
      <material
        name="green">
        <color
          rgba="0 1 0 1" />
      </material>
    </visual>
    <collision>
      <origin
        xyz="0 0 0"
        rpy="0 0 0" />
      <geometry>
        <mesh
          filename="RF_Link.STL" />
      </geometry>
    </collision>
  </link>
  <joint
    name="rear_fork"
    type="continuous">
    <origin
      xyz="-0.550000000000001 0 0.0599999999999999"
      rpy="0 0 0" />
    <parent
      link="base_link" />
    <child
      link="RF_Link" />
    <axis
      xyz="0 0 1" />
  </joint>
  <link
    name="RW_Link">
    <inertial>
      <origin
        xyz="-1.389111048411E-12 -1.50546641730642E-06 -1.07969189144796E-12"
        rpy="0 0 0" />
      <mass
        value="1" />
      <inertia
        ixx="0.141368359203212"
        ixy="2.26252468230997E-14"
        ixz="-0.000100890791063385"
        iyy="0.280788651932695"
        iyz="2.04413972584876E-14"
        izz="0.141419082377265" />
    </inertial>
    <visual>
      <origin
        xyz="0 0 0"
        rpy="0 0 0" />
      <geometry>
        <mesh
          filename="RW_Link.STL" />
      </geometry>
      <material
        name="red">
        <color
          rgba="1 0 0 1" />
      </material>
    </visual>
    <collision>
      <origin
        xyz="0 0 0"
        rpy="0 0 0" />
      <geometry>
        <mesh
          filename="RW_Link.STL" />
      </geometry>
    </collision>
  </link>
  <joint
    name="rear_wheel"
    type="continuous">
    <origin
      xyz="0 0 -0.55"
      rpy="0 0 0" />
    <parent
      link="RF_Link" />
    <child
      link="RW_Link" />
    <axis
      xyz="0 -1 0" />
  </joint>
</robot>